<?xml version="1.0" encoding="utf-8"?>
<!-- =================================================================================== -->
<!-- |    This document was autogenerated by xacro from ur5e_robot.urdf.xacro          | -->
<!-- |    EDITING THIS FILE BY HAND IS NOT RECOMMENDED                                 | -->
<!-- =================================================================================== -->
<robot name="ur5_gripper" xmlns:xacro="http://ros.org/wiki/xacro">
  <xacro:macro name="ur5_gripper"
    params="parent:=world *origin name:=ur5_gripper">
    <joint name="base_joint" type="fixed">
      <xacro:insert_block name="origin" />
      <parent link="${parent}" />
      <child link="base_link" />
    </joint>
    <link name="base_link" />
    <link name="base_link_inertia">
      <visual>
        <origin rpy="0 0 3.141592653589793" xyz="0 0 0" />
        <geometry>
          <mesh filename="file://$(find gazebo_env)/meshes/ur5/visual/base.dae" />
        </geometry>
      </visual>
      <collision>
        <origin rpy="0 0 3.141592653589793" xyz="0 0 0" />
        <geometry>
          <mesh filename="file://$(find gazebo_env)/meshes/ur5/collision/base.stl" />
        </geometry>
      </collision>
      <inertial>
        <mass value="4.0" />
        <origin rpy="0 0 0" xyz="0 0 0" />
        <inertia ixx="0.00443333156" ixy="0.0" ixz="0.0" iyy="0.00443333156" iyz="0.0" izz="0.0072" />
      </inertial>
    </link>
    <link name="shoulder_link">
      <visual>
        <origin rpy="0 0 3.141592653589793" xyz="0 0 0" />
        <geometry>
          <mesh filename="file://$(find gazebo_env)/meshes/ur5/visual/shoulder.dae" />
        </geometry>
      </visual>
      <collision>
        <origin rpy="0 0 3.141592653589793" xyz="0 0 0" />
        <geometry>
          <mesh filename="file://$(find gazebo_env)/meshes/ur5/collision/shoulder.stl" />
        </geometry>
      </collision>
      <inertial>
        <mass value="3.7" />
        <origin rpy="0 0 0" xyz="0 0 0" />
        <inertia ixx="0.014972352344389999" ixy="0.0" ixz="0.0" iyy="0.014972352344389999" iyz="0.0"
          izz="0.01040625" />
      </inertial>
    </link>
    <link name="upper_arm_link">
      <visual>
        <origin rpy="1.5707963267948966 0 -1.5707963267948966" xyz="0 0 0.13585" />
        <geometry>
          <mesh filename="file://$(find gazebo_env)/meshes/ur5/visual/upperarm.dae" />
        </geometry>
      </visual>
      <collision>
        <origin rpy="1.5707963267948966 0 -1.5707963267948966" xyz="0 0 0.13585" />
        <geometry>
          <mesh filename="file://$(find gazebo_env)/meshes/ur5/collision/upperarm.stl" />
        </geometry>
      </collision>
      <inertial>
        <mass value="8.393" />
        <origin rpy="0 1.5707963267948966 0" xyz="-0.2125 0.0 0.136" />
        <inertia ixx="0.1338857818623325" ixy="0.0" ixz="0.0" iyy="0.1338857818623325" iyz="0.0"
          izz="0.0151074" />
      </inertial>
    </link>
    <link name="forearm_link">
      <visual>
        <origin rpy="1.5707963267948966 0 -1.5707963267948966" xyz="0 0 0.0165" />
        <geometry>
          <mesh filename="file://$(find gazebo_env)/meshes/ur5/visual/forearm.dae" />
        </geometry>
      </visual>
      <collision>
        <origin rpy="1.5707963267948966 0 -1.5707963267948966" xyz="0 0 0.0165" />
        <geometry>
          <mesh filename="file://$(find gazebo_env)/meshes/ur5/collision/forearm.stl" />
        </geometry>
      </collision>
      <inertial>
        <mass value="2.275" />
        <origin rpy="0 1.5707963267948966 0" xyz="-0.196125 0.0 0.0165" />
        <inertia ixx="0.03121679102890359" ixy="0.0" ixz="0.0" iyy="0.03121679102890359" iyz="0.0"
          izz="0.004095" />
      </inertial>
    </link>
    <link name="wrist_1_link">
      <visual>
        <origin rpy="1.5707963267948966 0 0" xyz="0 0 -0.093" />
        <geometry>
          <mesh filename="file://$(find gazebo_env)/meshes/ur5/visual/wrist1.dae" />
        </geometry>
      </visual>
      <collision>
        <origin rpy="1.5707963267948966 0 0" xyz="0 0 -0.093" />
        <geometry>
          <mesh filename="file://$(find gazebo_env)/meshes/ur5/collision/wrist1.stl" />
        </geometry>
      </collision>
      <inertial>
        <mass value="1.219" />
        <origin rpy="0 0 0" xyz="0 0 0" />
        <inertia ixx="0.0020138887777775" ixy="0.0" ixz="0.0" iyy="0.0020138887777775" iyz="0.0"
          izz="0.0021942" />
      </inertial>
    </link>
    <link name="wrist_2_link">
      <visual>
        <origin rpy="0 0 0" xyz="0 0 -0.095" />
        <geometry>
          <mesh filename="file://$(find gazebo_env)/meshes/ur5/visual/wrist2.dae" />
        </geometry>
      </visual>
      <collision>
        <origin rpy="0 0 0" xyz="0 0 -0.095" />
        <geometry>
          <mesh filename="file://$(find gazebo_env)/meshes/ur5/collision/wrist2.stl" />
        </geometry>
      </collision>
      <inertial>
        <mass value="1.219" />
        <origin rpy="0 0 0" xyz="0 0 0" />
        <inertia ixx="0.0018310388509175" ixy="0.0" ixz="0.0" iyy="0.0018310388509175" iyz="0.0"
          izz="0.0021942" />
      </inertial>
    </link>
    <link name="wrist_3_link">
      <visual>
        <origin rpy="1.5707963267948966 0 0" xyz="0 0 -0.0818" />
        <geometry>
          <mesh filename="file://$(find gazebo_env)/meshes/ur5/visual/wrist3.dae" />
        </geometry>
      </visual>
      <collision>
        <origin rpy="1.5707963267948966 0 0" xyz="0 0 -0.0818" />
        <geometry>
          <mesh filename="file://$(find gazebo_env)/meshes/ur5/collision/wrist3.stl" />
        </geometry>
      </collision>
      <inertial>
        <mass value="0.1879" />
        <origin rpy="0 0 0" xyz="0.0 0.0 -0.01525" />
        <inertia ixx="8.062472608343e-05" ixy="0.0" ixz="0.0" iyy="8.062472608343e-05" iyz="0.0"
          izz="0.0001321171875" />
      </inertial>
    </link>
    <!-- joints - main serial chain -->
    <joint name="base_link-base_link_inertia" type="fixed">
      <parent link="base_link" />
      <child link="base_link_inertia" />
      <!-- 'base_link' is REP-103 aligned (so X+ forward), while the internal
             frames of the robot/controller have X+ pointing backwards.
             Use the joint between 'base_link' and 'base_link_inertia' (a dummy
             link/frame) to introduce the necessary rotation over Z (of pi rad).
        -->
      <origin rpy="0 0 3.141592653589793" xyz="0 0 0" />
    </joint>
    <joint name="shoulder_pan_joint" type="revolute">
      <parent link="base_link_inertia" />
      <child link="shoulder_link" />
      <origin rpy="0 0 0" xyz="0 0 0.089159" />
      <axis xyz="0 0 1" />
      <limit effort="150.0" lower="-6.283185307179586" upper="6.283185307179586"
        velocity="3.141592653589793" />
      <safety_controller k_position="20" k_velocity="0.0" soft_lower_limit="-6.133185307179586"
        soft_upper_limit="6.133185307179586" />
      <dynamics damping="0" friction="0" />
    </joint>
    <joint name="shoulder_lift_joint" type="revolute">
      <parent link="shoulder_link" />
      <child link="upper_arm_link" />
      <origin rpy="1.570796327 0 0" xyz="0 0 0" />
      <axis xyz="0 0 1" />
      <limit effort="150.0" lower="-6.283185307179586" upper="6.283185307179586"
        velocity="3.141592653589793" />
      <safety_controller k_position="20" k_velocity="0.0" soft_lower_limit="-6.133185307179586"
        soft_upper_limit="6.133185307179586" />
      <dynamics damping="0" friction="0" />
    </joint>
    <joint name="elbow_joint" type="revolute">
      <parent link="upper_arm_link" />
      <child link="forearm_link" />
      <origin rpy="0 0 0" xyz="-0.425 0 0" />
      <axis xyz="0 0 1" />
      <limit effort="150.0" lower="-3.141592653589793" upper="3.141592653589793"
        velocity="3.141592653589793" />
      <safety_controller k_position="20" k_velocity="0.0" soft_lower_limit="-2.991592653589793"
        soft_upper_limit="2.991592653589793" />
      <dynamics damping="0" friction="0" />
    </joint>
    <joint name="wrist_1_joint" type="revolute">
      <parent link="forearm_link" />
      <child link="wrist_1_link" />
      <origin rpy="0 0 0" xyz="-0.39225 0 0.10915" />
      <axis xyz="0 0 1" />
      <limit effort="28.0" lower="-6.283185307179586" upper="6.283185307179586"
        velocity="3.141592653589793" />
      <safety_controller k_position="20" k_velocity="0.0" soft_lower_limit="-6.133185307179586"
        soft_upper_limit="6.133185307179586" />
      <dynamics damping="0" friction="0" />
    </joint>
    <joint name="wrist_2_joint" type="revolute">
      <parent link="wrist_1_link" />
      <child link="wrist_2_link" />
      <origin rpy="1.570796327 0 0" xyz="0 -0.09465 -1.941303950897609e-11" />
      <axis xyz="0 0 1" />
      <limit effort="28.0" lower="-6.283185307179586" upper="6.283185307179586"
        velocity="3.141592653589793" />
      <safety_controller k_position="20" k_velocity="0.0" soft_lower_limit="-6.133185307179586"
        soft_upper_limit="6.133185307179586" />
      <dynamics damping="0" friction="0" />
    </joint>
    <joint name="wrist_3_joint" type="revolute">
      <parent link="wrist_2_link" />
      <child link="wrist_3_link" />
      <origin rpy="1.570796326589793 3.141592653589793 3.141592653589793"
        xyz="0 0.0823 -1.688001216681175e-11" />
      <axis xyz="0 0 1" />
      <limit effort="28.0" lower="-6.283185307179586" upper="6.283185307179586"
        velocity="3.141592653589793" />
      <safety_controller k_position="20" k_velocity="0.0" soft_lower_limit="-6.133185307179586"
        soft_upper_limit="6.133185307179586" />
      <dynamics damping="0" friction="0" />
    </joint>
    <link name="ft_frame" />
    <joint name="wrist_3_link-ft_frame" type="fixed">
      <parent link="wrist_3_link" />
      <child link="ft_frame" />
      <origin rpy="3.141592653589793 0 0" xyz="0 0 0" />
    </joint>
    <!-- ROS-Industrial 'base' frame - base_link to UR 'Base' Coordinates transform -->
    <link name="base" />
    <joint name="base_link-base_fixed_joint" type="fixed">
      <!-- Note the rotation over Z of pi radians - as base_link is REP-103
             aligned (i.e., has X+ forward, Y+ left and Z+ up), this is needed
             to correctly align 'base' with the 'Base' coordinate system of
             the UR controller.
        -->
      <origin rpy="0 0 3.141592653589793" xyz="0 0 0" />
      <parent link="base_link" />
      <child link="base" />
    </joint>
    <!-- ROS-Industrial 'flange' frame - attachment point for EEF models -->
    <link name="flange" />
    <joint name="wrist_3-flange" type="fixed">
      <parent link="wrist_3_link" />
      <child link="flange" />
      <origin rpy="0 -1.5707963267948966 -1.5707963267948966" xyz="0 0 0" />
    </joint>
    <!-- ROS-Industrial 'tool0' frame - all-zeros tool frame -->
    <link name="tool0" />
    <joint name="flange-tool0" type="fixed">
      <!-- default toolframe - X+ left, Y+ up, Z+ front -->
      <origin rpy="1.5707963267948966 0 1.5707963267948966" xyz="0 0 0" />
      <parent link="flange" />
      <child link="tool0" />
    </joint>
    <!-- <joint name="arm_gripper_joint" type="fixed">
      <parent link="wrist_3_link" />
      <child link="robotiq_85_base_link" />
      <origin rpy="0.0 -1.5708 0.0" xyz="0.0 0.0 0.0" />
    </joint> -->
    <joint name="arm_gripper_adapter_joint" type="fixed">
      <parent link="wrist_3_link" />
      <child link="adapter_link" />
      <origin rpy="0.0 0.0 0.0" xyz="0.0 0.0 0.0" />
    </joint>
    <gazebo reference="adapter_link">
      <material>Gazebo/Black</material>
    </gazebo>
    <link name="adapter_link">
      <visual>
        <geometry>
          <cylinder length="0.016" radius="0.035" />
        </geometry>
        <origin rpy="0 0 0" xyz="0 0 0.008" />
      </visual>
      <inertial>
        <origin rpy="0 0 0" xyz="0 0 0" />
        <mass value="1.1285806309" />
        <inertia ixx="0.0026052565" ixy="0.0" ixz="0.0" iyy="0.0039897229" iyz="0"
          izz="0.0047048591" />
      </inertial>
    </link>
    <joint name="arm_gripper_joint" type="fixed">
      <parent link="adapter_link" />
      <child link="robotiq_85_base_link" />
      <origin rpy="0.0 -1.5708 1.5708" xyz="0.0 0.0 0.016" />
    </joint>
    <link name="robotiq_85_base_link">
      <visual>
        <origin rpy="0 0 0" xyz="0 0 0" />
        <geometry>
          <mesh
            filename="file://$(find
    gazebo_env)/meshes/ur5e_nvidia/robotiq_85_gripper/visual/robotiq_85_base_link.dae" />
        </geometry>
      </visual>
      <collision>
        <geometry>
          <mesh
            filename="file://$(find
    gazebo_env)/meshes/ur5e_nvidia/robotiq_85_gripper/collision/robotiq_85_base_link.stl" />
        </geometry>
      </collision>
      <inertial>
        <mass value="0.636951" />
        <origin xyz="0.0 0.0 0.0" />
        <inertia ixx="0.000380" ixy="0.000000" ixz="0.000000"
          iyx="0.000000" iyy="0.001110" iyz="0.000000"
          izx="0.000000" izy="0.000000" izz="0.001171" />
      </inertial>
    </link>
    <joint name="robotiq_85_left_knuckle_joint" type="revolute">
      <parent link="robotiq_85_base_link" />
      <child link="robotiq_85_left_knuckle_link" />
      <axis xyz="0 0 1" />
      <origin rpy="3.14 0.0 0.0" xyz="0.05490451627 0.03060114443 0.0" />
      <limit lower="0.0" upper="0.80285" velocity="3.14" effort="1000" />
    </joint>

    <joint name="robotiq_85_right_knuckle_joint" type="revolute">
      <parent link="robotiq_85_base_link" />
      <child link="robotiq_85_right_knuckle_link" />
      <axis xyz="0 0 1" />
      <origin rpy="0.0 0.0 0.0" xyz="0.05490451627 -0.03060114443 0.0" />
      <limit lower="-3.14" upper="3.14" velocity="3.14" effort="1000" />
      <mimic joint="robotiq_85_left_knuckle_joint" />
    </joint>

    <link name="robotiq_85_left_knuckle_link">
      <visual>
        <origin rpy="0 0 0" xyz="0 0 0" />
        <geometry>
          <mesh
            filename="file://$(find
    gazebo_env)/meshes/ur5e_nvidia/robotiq_85_gripper/visual/robotiq_85_knuckle_link.dae" />
        </geometry>
      </visual>
      <collision>
        <geometry>
          <mesh
            filename="file://$(find
    gazebo_env)/meshes/ur5e_nvidia/robotiq_85_gripper/collision/robotiq_85_knuckle_link.stl" />
        </geometry>
      </collision>
      <inertial>
        <mass value="0.018491" />
        <origin xyz="0.0 0.0 0.0" />
        <inertia ixx="0.000009" ixy="-0.000001" ixz="0.000000"
          iyx="-0.000001" iyy="0.000001" iyz="0.000000"
          izx="0.000000" izy="0.000000" izz="0.000010" />
      </inertial>
    </link>

    <link name="robotiq_85_right_knuckle_link">
      <visual>
        <origin rpy="0 0 0" xyz="0 0 0" />
        <geometry>
          <mesh
            filename="file://$(find
    gazebo_env)/meshes/ur5e_nvidia/robotiq_85_gripper/visual/robotiq_85_knuckle_link.dae" />
        </geometry>
      </visual>
      <collision>
        <geometry>
          <mesh
            filename="file://$(find
    gazebo_env)/meshes/ur5e_nvidia/robotiq_85_gripper/collision/robotiq_85_knuckle_link.stl" />
        </geometry>
      </collision>
      <inertial>
        <mass value="0.018491" />
        <origin xyz="0.0 0.0 0.0" />
        <inertia ixx="0.000009" ixy="-0.000001" ixz="0.000000"
          iyx="-0.000001" iyy="0.000001" iyz="0.000000"
          izx="0.000000" izy="0.000000" izz="0.000010" />
      </inertial>
    </link>

    <joint name="robotiq_85_left_finger_joint" type="fixed">
      <parent link="robotiq_85_left_knuckle_link" />
      <child link="robotiq_85_left_finger_link" />
      <origin xyz="-0.00408552455 -0.03148604435 0.0" rpy="0 0 0" />
    </joint>

    <joint name="robotiq_85_right_finger_joint" type="fixed">
      <parent link="robotiq_85_right_knuckle_link" />
      <child link="robotiq_85_right_finger_link" />
      <origin xyz="-0.00408552455 -0.03148604435 0.0" rpy="0 0 0" />
    </joint>

    <link name="robotiq_85_left_finger_link">
      <visual>
        <origin rpy="0 0 0" xyz="0 0 0" />
        <geometry>
          <mesh
            filename="file://$(find
    gazebo_env)/meshes/ur5e_nvidia/robotiq_85_gripper/visual/robotiq_85_finger_link.dae" />
        </geometry>
      </visual>
      <collision>
        <geometry>
          <mesh
            filename="file://$(find
    gazebo_env)/meshes/ur5e_nvidia/robotiq_85_gripper/collision/robotiq_85_finger_link.stl" />
        </geometry>
      </collision>
      <inertial>
        <mass value="0.027309" />
        <origin xyz="0.0 0.0 0.0" />
        <inertia ixx="0.000003" ixy="-0.000002" ixz="0.000000"
          iyx="-0.000002" iyy="0.000021" iyz="0.000000"
          izx="0.000000" izy="0.000000" izz="0.000020" />
      </inertial>
    </link>

    <link name="robotiq_85_right_finger_link">
      <visual>
        <origin rpy="0 0 0" xyz="0 0 0" />
        <geometry>
          <mesh
            filename="file://$(find
    gazebo_env)/meshes/ur5e_nvidia/robotiq_85_gripper/visual/robotiq_85_finger_link.dae" />
        </geometry>
      </visual>
      <collision>
        <geometry>
          <mesh
            filename="file://$(find
    gazebo_env)/meshes/ur5e_nvidia/robotiq_85_gripper/collision/robotiq_85_finger_link.stl" />
        </geometry>
      </collision>
      <inertial>
        <mass value="0.027309" />
        <origin xyz="0.0 0.0 0.0" />
        <inertia ixx="0.000003" ixy="-0.000002" ixz="0.000000"
          iyx="-0.000002" iyy="0.000021" iyz="0.000000"
          izx="0.000000" izy="0.000000" izz="0.000020" />
      </inertial>
    </link>

    <joint name="robotiq_85_left_inner_knuckle_joint" type="revolute">
      <parent link="robotiq_85_base_link" />
      <child link="robotiq_85_left_inner_knuckle_link" />
      <axis xyz="0 0 1" />
      <origin xyz="0.06142 0.0127 0" rpy="3.14 0.0 0.0" />
      <limit lower="-3.14" upper="3.14" velocity="3.14" effort="0.1" />
      <mimic joint="robotiq_85_left_knuckle_joint" offset="0" />
    </joint>

    <joint name="robotiq_85_right_inner_knuckle_joint" type="revolute">
      <parent link="robotiq_85_base_link" />
      <child link="robotiq_85_right_inner_knuckle_link" />
      <axis xyz="0 0 1" />
      <origin xyz="0.06142 -0.0127 0" rpy="0 0 0" />
      <limit lower="-3.14" upper="3.14" velocity="3.14" effort="0.1" />
      <mimic joint="robotiq_85_left_knuckle_joint" offset="0" />
    </joint>

    <link name="robotiq_85_left_inner_knuckle_link">
      <visual>
        <origin rpy="0 0 0" xyz="0 0 0" />
        <geometry>
          <mesh
            filename="file://$(find
    gazebo_env)/meshes/ur5e_nvidia/robotiq_85_gripper/visual/robotiq_85_inner_knuckle_link.dae" />
        </geometry>
      </visual>
      <collision>
        <geometry>
          <mesh
            filename="file://$(find
    gazebo_env)/meshes/ur5e_nvidia/robotiq_85_gripper/collision/robotiq_85_inner_knuckle_link.stl"
          />
        </geometry>
      </collision>
      <inertial>
        <mass value="0.029951" />
        <origin xyz="0.0 0.0 0.0" />
        <inertia ixx="0.000039" ixy="0.000000" ixz="0.000000"
          iyx="0.000000" iyy="0.000005" iyz="0.000000"
          izx="0.000000" izy="0.000000" izz="0.000035" />
      </inertial>
    </link>
    <link name="robotiq_85_right_inner_knuckle_link">
      <visual>
        <origin rpy="0 0 0" xyz="0 0 0" />
        <geometry>
          <mesh
            filename="file://$(find
    gazebo_env)/meshes/ur5e_nvidia/robotiq_85_gripper/visual/robotiq_85_inner_knuckle_link.dae" />
        </geometry>
      </visual>
      <collision>
        <geometry>
          <mesh
            filename="file://$(find
    gazebo_env)/meshes/ur5e_nvidia/robotiq_85_gripper/collision/robotiq_85_inner_knuckle_link.stl"
          />
        </geometry>
      </collision>
      <inertial>
        <mass value="0.029951" />
        <origin xyz="0.0 0.0 0.0" />
        <inertia ixx="0.000039" ixy="0.000000" ixz="0.000000"
          iyx="0.000000" iyy="0.000005" iyz="0.000000"
          izx="0.000000" izy="0.000000" izz="0.000035" />
      </inertial>
    </link>

    <joint name="robotiq_85_left_finger_tip_joint" type="revolute">
      <parent link="robotiq_85_left_inner_knuckle_link" />
      <child link="robotiq_85_left_finger_tip_link" />
      <axis xyz="0 0 1" />
      <origin xyz="0.04303959807 -0.03759940821 0.0" rpy="0.0 0.0 0.0" />
      <limit lower="-3.14" upper="3.14" velocity="3.14" effort="0.1" />
      <mimic joint="robotiq_85_left_knuckle_joint" multiplier="-1" />
    </joint>

    <joint name="robotiq_85_right_finger_tip_joint" type="revolute">
      <parent link="robotiq_85_right_inner_knuckle_link" />
      <child link="robotiq_85_right_finger_tip_link" />
      <axis xyz="0 0 1" />
      <origin rpy="0.0 0.0 0.0" xyz="0.04303959807 -0.03759940821  0.0" />
      <limit lower="-3.14" upper="3.14" velocity="3.14" effort="0.1" />
      <mimic joint="robotiq_85_left_knuckle_joint" multiplier="-1" />
    </joint>


    <link name="robotiq_85_left_finger_tip_link">
      <visual>
        <origin rpy="0 0 0" xyz="0 0 0" />
        <geometry>
          <mesh
            filename="file://$(find
    gazebo_env)/meshes/ur5e_nvidia/robotiq_85_gripper/visual/robotiq_85_finger_tip_link.dae" />
        </geometry>
      </visual>
      <collision>
        <geometry>
          <mesh
            filename="file://$(find
    gazebo_env)/meshes/ur5e_nvidia/robotiq_85_gripper/collision/robotiq_85_finger_tip_link.stl" />
        </geometry>
      </collision>
      <inertial>
        <mass value="0.019555" />
        <origin xyz="0.0 0.0 0.0" />
        <inertia ixx="0.000002" ixy="0.000000" ixz="0.000000"
          iyx="0.000000" iyy="0.000005" iyz="0.000000"
          izx="0.000000" izy="0.000000" izz="0.000006" />
      </inertial>
    </link>

    <link name="robotiq_85_right_finger_tip_link">
      <visual>
        <origin rpy="0 0 0" xyz="0 0 0" />
        <geometry>
          <mesh
            filename="file://$(find
    gazebo_env)/meshes/ur5e_nvidia/robotiq_85_gripper/visual/robotiq_85_finger_tip_link.dae" />
        </geometry>
      </visual>
      <collision>
        <geometry>
          <mesh
            filename="file://$(find
    gazebo_env)/meshes/ur5e_nvidia/robotiq_85_gripper/collision/robotiq_85_finger_tip_link.stl" />
        </geometry>
      </collision>
      <inertial>
        <mass value="0.019555" />
        <origin xyz="0.0 0.0 0.0" />
        <inertia ixx="0.000002" ixy="0.000000" ixz="0.000000"
          iyx="0.000000" iyy="0.000005" iyz="0.000000"
          izx="0.000000" izy="0.000000" izz="0.000006" />
      </inertial>
    </link>


    <!-- <link name="base_link">
      <visual>
        <origin rpy="0 0 0" xyz="0 0 0" />
        <geometry>
          <mesh filename="file://$(find gazebo_env)/meshes/ur5/visual/base.dae" />
        </geometry>
        <material name="LightGrey">
          <color rgba="0.7 0.7 0.7 1.0" />
        </material>
      </visual>
      <collision>
        <geometry>
          <mesh filename="file://$(find gazebo_env)/meshes/ur5/collision/base.stl"
            scale="1.0 1.0 1.0" />
        </geometry>
      </collision>
      <inertial>
        <mass value="4.0" />
        <origin rpy="0 0 0" xyz="0.0 0.0 0.0" />
        <inertia ixx="0.00443333156" ixy="0.0" ixz="0.0" iyy="0.00443333156" iyz="0.0" izz="0.0072" />
      </inertial>
    </link>
    <joint name="shoulder_pan_joint" type="revolute">
      <parent link="base_link" />
      <child link="shoulder_link" />
      <origin rpy="0.0 0.0 0.0" xyz="0.0 0.0 0.163" />
      <axis xyz="0 0 1" />
      <limit effort="150.0" lower="-6.28318530718" upper="6.28318530718" velocity="3.14" />
      <dynamics damping="0.0" friction="0.0" />
    </joint>
    <link name="shoulder_link">
      <visual>
        <origin rpy="0 0 0" xyz="0 0 0" />
        <geometry>
          <mesh filename="file://$(find gazebo_env)/meshes/ur5/visual/shoulder.dae" />
        </geometry>
        <material name="LightGrey">
          <color rgba="0.7 0.7 0.7 1.0" />
        </material>
      </visual>
      <collision>
        <geometry>
          <mesh filename="file://$(find gazebo_env)/meshes/ur5/collision/shoulder.stl"
            scale="1.0 1.0 1.0" />
        </geometry>
      </collision>
      <inertial>
        <mass value="3.7" />
        <origin rpy="0 0 0" xyz="0.0 0.0 0.0" />
        <inertia ixx="0.010267495893" ixy="0.0" ixz="0.0" iyy="0.010267495893" iyz="0.0"
          izz="0.00666" />
      </inertial>
    </link>
    <joint name="shoulder_lift_joint" type="revolute">
      <parent link="shoulder_link" />
      <child link="upper_arm_link" />
      <origin rpy="0.0 1.57079632679 0.0" xyz="0.0 0.138 0.0" />
      <axis xyz="0 1 0" />
      <limit effort="150.0" lower="-6.28318530718" upper="6.28318530718" velocity="3.14" />
      <dynamics damping="0.0" friction="0.0" />
    </joint>
    <link name="upper_arm_link">
      <visual>
        <origin rpy="0 0 0" xyz="0 0 0" />
        <origin rpy="0 0 0" xyz="0 0 0" />
        <geometry>
          <mesh filename="file://$(find gazebo_env)/meshes/ur5/visual/upperarm.dae" />
        </geometry>
        <material name="LightGrey">
          <color rgba="0.7 0.7 0.7 1.0" />
        </material>
      </visual>
      <collision>
        <geometry>
          <mesh filename="file://$(find gazebo_env)/meshes/ur5/collision/upperarm.stl"
            scale="1.0 1.0 1.0" />
        </geometry>
      </collision>
      <inertial>
        <mass value="8.393" />
        <origin rpy="0 0 0" xyz="0.0 0.0 0.2125" />
        <inertia ixx="0.133885781862" ixy="0.0" ixz="0.0" iyy="0.133885781862" iyz="0.0"
          izz="0.0151074" />
      </inertial>
    </link>
    <joint name="elbow_joint" type="revolute">
      <parent link="upper_arm_link" />
      <child link="forearm_link" />
      <origin rpy="0.0 0.0 0.0" xyz="0.0 -0.131 0.425" />
      <axis xyz="0 1 0" />
      <limit effort="150.0" lower="-3.14159265359" upper="3.14159265359" velocity="3.14" />
      <dynamics damping="0.0" friction="0.0" />
    </joint>
    <link name="forearm_link">
      <visual>
        <origin rpy="0 0 0" xyz="0 0 0" />
        <geometry>
          <mesh filename="file://$(find gazebo_env)/meshes/ur5/visual/forearm.dae" />
        </geometry>
        <material name="LightGrey">
          <color rgba="0.7 0.7 0.7 1.0" />
        </material>
      </visual>
      <collision>
        <geometry>
          <mesh filename="file://$(find gazebo_env)/meshes/ur5/collision/forearm.stl"
            scale="1.0 1.0 1.0" />
        </geometry>
      </collision>
      <inertial>
        <mass value="2.275" />
        <origin rpy="0 0 0" xyz="0.0 0.0 0.196" />
        <inertia ixx="0.0311796208615" ixy="0.0" ixz="0.0" iyy="0.0311796208615" iyz="0.0"
          izz="0.004095" />
      </inertial>
    </link>
    <joint name="wrist_1_joint" type="revolute">
      <parent link="forearm_link" />
      <child link="wrist_1_link" />
      <origin rpy="0.0 1.57079632679 0.0" xyz="0.0 0.0 0.392" />
      <axis xyz="0 1 0" />
      <limit effort="28.0" lower="-6.28318530718" upper="6.28318530718" velocity="6.28" />
      <dynamics damping="0.0" friction="0.0" />
    </joint>
    <link name="wrist_1_link">
      <visual>
        <origin rpy="0 0 0" xyz="0 0 0" />
        <geometry>
          <mesh filename="file://$(find gazebo_env)/meshes/ur5/visual/wrist1.dae" />
        </geometry>
        <material name="LightGrey">
          <color rgba="0.7 0.7 0.7 1.0" />
        </material>
      </visual>
      <collision>
        <geometry>
          <mesh filename="file://$(find gazebo_env)/meshes/ur5/collision/wrist1.stl"
            scale="1.0 1.0 1.0" />
        </geometry>
      </collision>
      <inertial>
        <mass value="1.219" />
        <origin rpy="0 0 0" xyz="0.0 0.127 0.0" />
        <inertia ixx="0.00255989897604" ixy="0.0" ixz="0.0" iyy="0.00255989897604" iyz="0.0"
          izz="0.0021942" />
      </inertial>
    </link>
    <joint name="wrist_2_joint" type="revolute">
      <parent link="wrist_1_link" />
      <child link="wrist_2_link" />
      <origin rpy="0.0 0.0 0.0" xyz="0.0 0.127 0.0" />
      <axis xyz="0 0 1" />
      <limit effort="28.0" lower="-6.28318530718" upper="6.28318530718" velocity="6.28" />
      <dynamics damping="0.0" friction="0.0" />
    </joint>
    <link name="wrist_2_link">
      <visual>
        <origin rpy="0 0 0" xyz="0 0 0" />
        <geometry>
          <mesh filename="file://$(find gazebo_env)/meshes/ur5/visual/wrist2.dae" />
        </geometry>
        <material name="LightGrey">
          <color rgba="0.7 0.7 0.7 1.0" />
        </material>
      </visual>
      <collision>
        <geometry>
          <mesh filename="file://$(find gazebo_env)/meshes/ur5/collision/wrist2.stl"
            scale="1.0 1.0 1.0" />
        </geometry>
      </collision>
      <inertial>
        <mass value="1.219" />
        <origin rpy="0 0 0" xyz="0.0 0.0 0.1" />
        <inertia ixx="0.00255989897604" ixy="0.0" ixz="0.0" iyy="0.00255989897604" iyz="0.0"
          izz="0.0021942" />
      </inertial>
    </link>
    <joint name="wrist_3_joint" type="revolute">
      <parent link="wrist_2_link" />
      <child link="wrist_3_link" />
      <origin rpy="0.0 0.0 0.0" xyz="0.0 0.0 0.1" />
      <axis xyz="0 1 0" />
      <limit effort="28.0" lower="-6.28318530718" upper="6.28318530718" velocity="6.28" />
      <dynamics damping="0.0" friction="0.0" />
    </joint>
    <link name="wrist_3_link">
      <visual>
        <origin rpy="0 0 0" xyz="0 0 0" />
        <geometry>
          <mesh filename="file://$(find gazebo_env)/meshes/ur5/visual/wrist3.dae" />
        </geometry>
        <material name="LightGrey">
          <color rgba="0.7 0.7 0.7 1.0" />
        </material>
      </visual>
      <collision>
        <geometry>
          <mesh filename="file://$(find gazebo_env)/meshes/ur5/collision/wrist3.stl"
            scale="1.0 1.0 1.0" />
        </geometry>
      </collision>
      <inertial>
        <mass value="0.1879" />
        <origin rpy="1.57079632679 0 0" xyz="0.0 0.0771 0.0" />
        <inertia ixx="9.89041005217e-05" ixy="0.0" ixz="0.0" iyy="9.89041005217e-05" iyz="0.0"
          izz="0.0001321171875" />
      </inertial>
    </link>
    <joint name="ee_fixed_joint" type="fixed">
      <parent link="wrist_3_link" />
      <child link="ee_link" />
      <origin rpy="0.0 0.0 1.57079632679" xyz="0.0 0.1 0.0" />
    </joint>
    <link name="ee_link">
      <collision>
        <geometry>
          <box size="0.01 0.01 0.01" />
        </geometry>
        <origin rpy="0 0 0" xyz="-0.01 0 0" />
      </collision>
    </link>
    <joint name="arm_gripper_joint" type="fixed">
      <parent link="wrist_3_link" />
      <child link="robotiq_85_base_link" />
      <origin rpy="0.0 0.0 1.5708" xyz="0.0 0.089 0.0" />
    </joint>
    <link name="robotiq_85_base_link">
      <visual>
        <origin rpy="0 0 0" xyz="0 0 0" />
        <geometry>
          <mesh
            filename="file://$(find
    gazebo_env)/meshes/ur5e_nvidia/robotiq_85_gripper/visual/robotiq_85_base_link.dae" />
        </geometry>
      </visual>
      <collision>
        <geometry>
          <mesh
            filename="file://$(find
    gazebo_env)/meshes/ur5e_nvidia/robotiq_85_gripper/collision/robotiq_85_base_link.stl" />
        </geometry>
      </collision>
      <inertial>
        <mass value="0.636951" />
        <origin xyz="0.0 0.0 0.0" />
        <inertia ixx="0.000380" ixy="0.000000" ixz="0.000000"
          iyx="0.000000" iyy="0.001110" iyz="0.000000"
          izx="0.000000" izy="0.000000" izz="0.001171" />
      </inertial>
    </link>
    <joint name="robotiq_85_left_knuckle_joint" type="revolute">
      <parent link="robotiq_85_base_link" />
      <child link="robotiq_85_left_knuckle_link" />
      <axis xyz="0 0 1" />
      <origin rpy="3.14 0.0 0.0" xyz="0.05490451627 0.03060114443 0.0" />
      <limit lower="0.0" upper="0.80285" velocity="3.14" effort="1000" />
    </joint>

    <joint name="robotiq_85_right_knuckle_joint" type="revolute">
      <parent link="robotiq_85_base_link" />
      <child link="robotiq_85_right_knuckle_link" />
      <axis xyz="0 0 1" />
      <origin rpy="0.0 0.0 0.0" xyz="0.05490451627 -0.03060114443 0.0" />
      <limit lower="-3.14" upper="3.14" velocity="3.14" effort="1000" />
      <mimic joint="robotiq_85_left_knuckle_joint" />
    </joint>

    <link name="robotiq_85_left_knuckle_link">
      <visual>
        <origin rpy="0 0 0" xyz="0 0 0" />
        <geometry>
          <mesh
            filename="file://$(find
    gazebo_env)/meshes/ur5e_nvidia/robotiq_85_gripper/visual/robotiq_85_knuckle_link.dae" />
        </geometry>
      </visual>
      <collision>
        <geometry>
          <mesh
            filename="file://$(find
    gazebo_env)/meshes/ur5e_nvidia/robotiq_85_gripper/collision/robotiq_85_knuckle_link.stl" />
        </geometry>
      </collision>
      <inertial>
        <mass value="0.018491" />
        <origin xyz="0.0 0.0 0.0" />
        <inertia ixx="0.000009" ixy="-0.000001" ixz="0.000000"
          iyx="-0.000001" iyy="0.000001" iyz="0.000000"
          izx="0.000000" izy="0.000000" izz="0.000010" />
      </inertial>
    </link>

    <link name="robotiq_85_right_knuckle_link">
      <visual>
        <origin rpy="0 0 0" xyz="0 0 0" />
        <geometry>
          <mesh
            filename="file://$(find
    gazebo_env)/meshes/ur5e_nvidia/robotiq_85_gripper/visual/robotiq_85_knuckle_link.dae" />
        </geometry>
      </visual>
      <collision>
        <geometry>
          <mesh
            filename="file://$(find
    gazebo_env)/meshes/ur5e_nvidia/robotiq_85_gripper/collision/robotiq_85_knuckle_link.stl" />
        </geometry>
      </collision>
      <inertial>
        <mass value="0.018491" />
        <origin xyz="0.0 0.0 0.0" />
        <inertia ixx="0.000009" ixy="-0.000001" ixz="0.000000"
          iyx="-0.000001" iyy="0.000001" iyz="0.000000"
          izx="0.000000" izy="0.000000" izz="0.000010" />
      </inertial>
    </link>

    <joint name="robotiq_85_left_finger_joint" type="fixed">
      <parent link="robotiq_85_left_knuckle_link" />
      <child link="robotiq_85_left_finger_link" />
      <origin xyz="-0.00408552455 -0.03148604435 0.0" rpy="0 0 0" />
    </joint>

    <joint name="robotiq_85_right_finger_joint" type="fixed">
      <parent link="robotiq_85_right_knuckle_link" />
      <child link="robotiq_85_right_finger_link" />
      <origin xyz="-0.00408552455 -0.03148604435 0.0" rpy="0 0 0" />
    </joint>

    <link name="robotiq_85_left_finger_link">
      <visual>
        <origin rpy="0 0 0" xyz="0 0 0" />
        <geometry>
          <mesh
            filename="file://$(find
    gazebo_env)/meshes/ur5e_nvidia/robotiq_85_gripper/visual/robotiq_85_finger_link.dae" />
        </geometry>
      </visual>
      <collision>
        <geometry>
          <mesh
            filename="file://$(find
    gazebo_env)/meshes/ur5e_nvidia/robotiq_85_gripper/collision/robotiq_85_finger_link.stl" />
        </geometry>
      </collision>
      <inertial>
        <mass value="0.027309" />
        <origin xyz="0.0 0.0 0.0" />
        <inertia ixx="0.000003" ixy="-0.000002" ixz="0.000000"
          iyx="-0.000002" iyy="0.000021" iyz="0.000000"
          izx="0.000000" izy="0.000000" izz="0.000020" />
      </inertial>
    </link>

    <link name="robotiq_85_right_finger_link">
      <visual>
        <origin rpy="0 0 0" xyz="0 0 0" />
        <geometry>
          <mesh
            filename="file://$(find
    gazebo_env)/meshes/ur5e_nvidia/robotiq_85_gripper/visual/robotiq_85_finger_link.dae" />
        </geometry>
      </visual>
      <collision>
        <geometry>
          <mesh
            filename="file://$(find
    gazebo_env)/meshes/ur5e_nvidia/robotiq_85_gripper/collision/robotiq_85_finger_link.stl" />
        </geometry>
      </collision>
      <inertial>
        <mass value="0.027309" />
        <origin xyz="0.0 0.0 0.0" />
        <inertia ixx="0.000003" ixy="-0.000002" ixz="0.000000"
          iyx="-0.000002" iyy="0.000021" iyz="0.000000"
          izx="0.000000" izy="0.000000" izz="0.000020" />
      </inertial>
    </link>

    <joint name="robotiq_85_left_inner_knuckle_joint" type="revolute">
      <parent link="robotiq_85_base_link" />
      <child link="robotiq_85_left_inner_knuckle_link" />
      <axis xyz="0 0 1" />
      <origin xyz="0.06142 0.0127 0" rpy="3.14 0.0 0.0" />
      <limit lower="-3.14" upper="3.14" velocity="3.14" effort="0.1" />
      <mimic joint="robotiq_85_left_knuckle_joint" offset="0" />
    </joint>

    <joint name="robotiq_85_right_inner_knuckle_joint" type="revolute">
      <parent link="robotiq_85_base_link" />
      <child link="robotiq_85_right_inner_knuckle_link" />
      <axis xyz="0 0 1" />
      <origin xyz="0.06142 -0.0127 0" rpy="0 0 0" />
      <limit lower="-3.14" upper="3.14" velocity="3.14" effort="0.1" />
      <mimic joint="robotiq_85_left_knuckle_joint" offset="0" />
    </joint>

    <link name="robotiq_85_left_inner_knuckle_link">
      <visual>
        <origin rpy="0 0 0" xyz="0 0 0" />
        <geometry>
          <mesh
            filename="file://$(find
    gazebo_env)/meshes/ur5e_nvidia/robotiq_85_gripper/visual/robotiq_85_inner_knuckle_link.dae" />
        </geometry>
      </visual>
      <collision>
        <geometry>
          <mesh
            filename="file://$(find
    gazebo_env)/meshes/ur5e_nvidia/robotiq_85_gripper/collision/robotiq_85_inner_knuckle_link.stl"
    />
        </geometry>
      </collision>
      <inertial>
        <mass value="0.029951" />
        <origin xyz="0.0 0.0 0.0" />
        <inertia ixx="0.000039" ixy="0.000000" ixz="0.000000"
          iyx="0.000000" iyy="0.000005" iyz="0.000000"
          izx="0.000000" izy="0.000000" izz="0.000035" />
      </inertial>
    </link>
    <link name="robotiq_85_right_inner_knuckle_link">
      <visual>
        <origin rpy="0 0 0" xyz="0 0 0" />
        <geometry>
          <mesh
            filename="file://$(find
    gazebo_env)/meshes/ur5e_nvidia/robotiq_85_gripper/visual/robotiq_85_inner_knuckle_link.dae" />
        </geometry>
      </visual>
      <collision>
        <geometry>
          <mesh
            filename="file://$(find
    gazebo_env)/meshes/ur5e_nvidia/robotiq_85_gripper/collision/robotiq_85_inner_knuckle_link.stl"
    />
        </geometry>
      </collision>
      <inertial>
        <mass value="0.029951" />
        <origin xyz="0.0 0.0 0.0" />
        <inertia ixx="0.000039" ixy="0.000000" ixz="0.000000"
          iyx="0.000000" iyy="0.000005" iyz="0.000000"
          izx="0.000000" izy="0.000000" izz="0.000035" />
      </inertial>
    </link>

    <joint name="robotiq_85_left_finger_tip_joint" type="revolute">
      <parent link="robotiq_85_left_inner_knuckle_link" />
      <child link="robotiq_85_left_finger_tip_link" />
      <axis xyz="0 0 1" />
      <origin xyz="0.04303959807 -0.03759940821 0.0" rpy="0.0 0.0 0.0" />
      <limit lower="-3.14" upper="3.14" velocity="3.14" effort="0.1" />
      <mimic joint="robotiq_85_left_knuckle_joint" multiplier="-1" />
    </joint>

    <joint name="robotiq_85_right_finger_tip_joint" type="revolute">
      <parent link="robotiq_85_right_inner_knuckle_link" />
      <child link="robotiq_85_right_finger_tip_link" />
      <axis xyz="0 0 1" />
      <origin rpy="0.0 0.0 0.0" xyz="0.04303959807 -0.03759940821  0.0" />
      <limit lower="-3.14" upper="3.14" velocity="3.14" effort="0.1" />
      <mimic joint="robotiq_85_left_knuckle_joint" multiplier="-1" />
    </joint>


    <link name="robotiq_85_left_finger_tip_link">
      <visual>
        <origin rpy="0 0 0" xyz="0 0 0" />
        <geometry>
          <mesh
            filename="file://$(find
    gazebo_env)/meshes/ur5e_nvidia/robotiq_85_gripper/visual/robotiq_85_finger_tip_link.dae" />
        </geometry>
      </visual>
      <collision>
        <geometry>
          <mesh
            filename="file://$(find
    gazebo_env)/meshes/ur5e_nvidia/robotiq_85_gripper/collision/robotiq_85_finger_tip_link.stl" />
        </geometry>
      </collision>
      <inertial>
        <mass value="0.019555" />
        <origin xyz="0.0 0.0 0.0" />
        <inertia ixx="0.000002" ixy="0.000000" ixz="0.000000"
          iyx="0.000000" iyy="0.000005" iyz="0.000000"
          izx="0.000000" izy="0.000000" izz="0.000006" />
      </inertial>
    </link>

    <link name="robotiq_85_right_finger_tip_link">
      <visual>
        <origin rpy="0 0 0" xyz="0 0 0" />
        <geometry>
          <mesh
            filename="file://$(find
    gazebo_env)/meshes/ur5e_nvidia/robotiq_85_gripper/visual/robotiq_85_finger_tip_link.dae" />
        </geometry>
      </visual>
      <collision>
        <geometry>
          <mesh
            filename="file://$(find
    gazebo_env)/meshes/ur5e_nvidia/robotiq_85_gripper/collision/robotiq_85_finger_tip_link.stl" />
        </geometry>
      </collision>
      <inertial>
        <mass value="0.019555" />
        <origin xyz="0.0 0.0 0.0" />
        <inertia ixx="0.000002" ixy="0.000000" ixz="0.000000"
          iyx="0.000000" iyy="0.000005" iyz="0.000000"
          izx="0.000000" izy="0.000000" izz="0.000006" />
      </inertial>
    </link>


    <link name="tool0" />
    <joint name="wrist_3_link-tool0_fixed_joint" type="fixed">
      <origin rpy="-1.57079632679 0 0" xyz="0 0.1 0" />
      <parent link="wrist_3_link" />
      <child link="tool0" />
    </joint>

    <gazebo>
      <plugin name="no_physics" filename="libno_physics_plugin.so" />
    </gazebo>
    <gazebo>
      <plugin name="ur5e_control" filename="libur5e_control_plugin.so" />
    </gazebo> -->
    <!-- <gazebo>
      <plugin name="no_physics" filename="libno_physics_plugin.so" />
    </gazebo>
    <gazebo>
      <plugin name="ur5e_control" filename="libur5e_control_plugin.so" />
    </gazebo> -->
  </xacro:macro>
</robot>