<?xml version="1.0" encoding="utf-8"?>
<!-- =================================================================================== -->
<!-- |    This document was autogenerated by xacro from ur5e_robot.urdf.xacro          | -->
<!-- |    EDITING THIS FILE BY HAND IS NOT RECOMMENDED                                 | -->
<!-- =================================================================================== -->
<robot name="ur5e_gripper" xmlns:xacro="http://ros.org/wiki/xacro">
  <xacro:macro name="ur5e_gripper"
    params="parent:=world *origin name:=ur5e_gripper">
    <joint name="arm_gripper_joint" type="fixed">
      <xacro:insert_block name="origin" />
      <parent link="${parent}" />
      <child link="robotiq_85_base_link" />
    </joint>
    <link name="robotiq_85_base_link">
      <visual>
        <origin rpy="0 0 0" xyz="0 0 0" />
        <geometry>
          <mesh
            filename="file://$(find gazebo_env)/meshes/ur5e_nvidia/robotiq_85_gripper/visual/robotiq_85_base_link.dae" />
        </geometry>
      </visual>
      <collision>
        <geometry>
          <mesh
            filename="file://$(find gazebo_env)/meshes/ur5e_nvidia/robotiq_85_gripper/collision/robotiq_85_base_link.stl" />
        </geometry>
      </collision>
      <inertial>
        <mass value="0.636951" />
        <origin xyz="0.0 0.0 0.0" />
        <inertia ixx="0.000380" ixy="0.000000" ixz="0.000000"
          iyx="0.000000" iyy="0.001110" iyz="0.000000"
          izx="0.000000" izy="0.000000" izz="0.001171" />
      </inertial>
    </link>
    <joint name="robotiq_85_left_knuckle_joint" type="revolute">
      <parent link="robotiq_85_base_link" />
      <child link="robotiq_85_left_knuckle_link" />
      <axis xyz="0 0 1" />
      <origin rpy="3.14 0.0 0.0" xyz="0.05490451627 0.03060114443 0.0" />
      <limit lower="0.0" upper="0.80285" velocity="3.14" effort="1000" />
    </joint>

    <joint name="robotiq_85_right_knuckle_joint" type="revolute">
      <parent link="robotiq_85_base_link" />
      <child link="robotiq_85_right_knuckle_link" />
      <axis xyz="0 0 1" />
      <origin rpy="0.0 0.0 0.0" xyz="0.05490451627 -0.03060114443 0.0" />
      <limit lower="-3.14" upper="3.14" velocity="3.14" effort="1000" />
      <mimic joint="robotiq_85_left_knuckle_joint" />
    </joint>

    <link name="robotiq_85_left_knuckle_link">
      <visual>
        <origin rpy="0 0 0" xyz="0 0 0" />
        <geometry>
          <mesh
            filename="file://$(find gazebo_env)/meshes/ur5e_nvidia/robotiq_85_gripper/visual/robotiq_85_knuckle_link.dae" />
        </geometry>
      </visual>
      <collision>
        <geometry>
          <mesh
            filename="file://$(find gazebo_env)/meshes/ur5e_nvidia/robotiq_85_gripper/collision/robotiq_85_knuckle_link.stl" />
        </geometry>
      </collision>
      <inertial>
        <mass value="0.018491" />
        <origin xyz="0.0 0.0 0.0" />
        <inertia ixx="0.000009" ixy="-0.000001" ixz="0.000000"
          iyx="-0.000001" iyy="0.000001" iyz="0.000000"
          izx="0.000000" izy="0.000000" izz="0.000010" />
      </inertial>
    </link>

    <link name="robotiq_85_right_knuckle_link">
      <visual>
        <origin rpy="0 0 0" xyz="0 0 0" />
        <geometry>
          <mesh
            filename="file://$(find gazebo_env)/meshes/ur5e_nvidia/robotiq_85_gripper/visual/robotiq_85_knuckle_link.dae" />
        </geometry>
      </visual>
      <collision>
        <geometry>
          <mesh
            filename="file://$(find gazebo_env)/meshes/ur5e_nvidia/robotiq_85_gripper/collision/robotiq_85_knuckle_link.stl" />
        </geometry>
      </collision>
      <inertial>
        <mass value="0.018491" />
        <origin xyz="0.0 0.0 0.0" />
        <inertia ixx="0.000009" ixy="-0.000001" ixz="0.000000"
          iyx="-0.000001" iyy="0.000001" iyz="0.000000"
          izx="0.000000" izy="0.000000" izz="0.000010" />
      </inertial>
    </link>

    <joint name="robotiq_85_left_finger_joint" type="fixed">
      <parent link="robotiq_85_left_knuckle_link" />
      <child link="robotiq_85_left_finger_link" />
      <origin xyz="-0.00408552455 -0.03148604435 0.0" rpy="0 0 0" />
    </joint>

    <joint name="robotiq_85_right_finger_joint" type="fixed">
      <parent link="robotiq_85_right_knuckle_link" />
      <child link="robotiq_85_right_finger_link" />
      <origin xyz="-0.00408552455 -0.03148604435 0.0" rpy="0 0 0" />
    </joint>

    <link name="robotiq_85_left_finger_link">
      <visual>
        <origin rpy="0 0 0" xyz="0 0 0" />
        <geometry>
          <mesh
            filename="file://$(find gazebo_env)/meshes/ur5e_nvidia/robotiq_85_gripper/visual/robotiq_85_finger_link.dae" />
        </geometry>
      </visual>
      <collision>
        <geometry>
          <mesh
            filename="file://$(find gazebo_env)/meshes/ur5e_nvidia/robotiq_85_gripper/collision/robotiq_85_finger_link.stl" />
        </geometry>
      </collision>
      <inertial>
        <mass value="0.027309" />
        <origin xyz="0.0 0.0 0.0" />
        <inertia ixx="0.000003" ixy="-0.000002" ixz="0.000000"
          iyx="-0.000002" iyy="0.000021" iyz="0.000000"
          izx="0.000000" izy="0.000000" izz="0.000020" />
      </inertial>
    </link>

    <link name="robotiq_85_right_finger_link">
      <visual>
        <origin rpy="0 0 0" xyz="0 0 0" />
        <geometry>
          <mesh
            filename="file://$(find gazebo_env)/meshes/ur5e_nvidia/robotiq_85_gripper/visual/robotiq_85_finger_link.dae" />
        </geometry>
      </visual>
      <collision>
        <geometry>
          <mesh
            filename="file://$(find gazebo_env)/meshes/ur5e_nvidia/robotiq_85_gripper/collision/robotiq_85_finger_link.stl" />
        </geometry>
      </collision>
      <inertial>
        <mass value="0.027309" />
        <origin xyz="0.0 0.0 0.0" />
        <inertia ixx="0.000003" ixy="-0.000002" ixz="0.000000"
          iyx="-0.000002" iyy="0.000021" iyz="0.000000"
          izx="0.000000" izy="0.000000" izz="0.000020" />
      </inertial>
    </link>

    <joint name="robotiq_85_left_inner_knuckle_joint" type="revolute">
      <parent link="robotiq_85_base_link" />
      <child link="robotiq_85_left_inner_knuckle_link" />
      <axis xyz="0 0 1" />
      <origin xyz="0.06142 0.0127 0" rpy="3.14 0.0 0.0" />
      <limit lower="-3.14" upper="3.14" velocity="3.14" effort="0.1" />
      <mimic joint="robotiq_85_left_knuckle_joint" offset="0" />
    </joint>

    <joint name="robotiq_85_right_inner_knuckle_joint" type="revolute">
      <parent link="robotiq_85_base_link" />
      <child link="robotiq_85_right_inner_knuckle_link" />
      <axis xyz="0 0 1" />
      <origin xyz="0.06142 -0.0127 0" rpy="0 0 0" />
      <limit lower="-3.14" upper="3.14" velocity="3.14" effort="0.1" />
      <mimic joint="robotiq_85_left_knuckle_joint" offset="0" />
    </joint>

    <link name="robotiq_85_left_inner_knuckle_link">
      <visual>
        <origin rpy="0 0 0" xyz="0 0 0" />
        <geometry>
          <mesh
            filename="file://$(find gazebo_env)/meshes/ur5e_nvidia/robotiq_85_gripper/visual/robotiq_85_inner_knuckle_link.dae" />
        </geometry>
      </visual>
      <collision>
        <geometry>
          <mesh
            filename="file://$(find gazebo_env)/meshes/ur5e_nvidia/robotiq_85_gripper/collision/robotiq_85_inner_knuckle_link.stl" />
        </geometry>
      </collision>
      <inertial>
        <mass value="0.029951" />
        <origin xyz="0.0 0.0 0.0" />
        <inertia ixx="0.000039" ixy="0.000000" ixz="0.000000"
          iyx="0.000000" iyy="0.000005" iyz="0.000000"
          izx="0.000000" izy="0.000000" izz="0.000035" />
      </inertial>
    </link>
    <link name="robotiq_85_right_inner_knuckle_link">
      <visual>
        <origin rpy="0 0 0" xyz="0 0 0" />
        <geometry>
          <mesh
            filename="file://$(find gazebo_env)/meshes/ur5e_nvidia/robotiq_85_gripper/visual/robotiq_85_inner_knuckle_link.dae" />
        </geometry>
      </visual>
      <collision>
        <geometry>
          <mesh
            filename="file://$(find gazebo_env)/meshes/ur5e_nvidia/robotiq_85_gripper/collision/robotiq_85_inner_knuckle_link.stl" />
        </geometry>
      </collision>
      <inertial>
        <mass value="0.029951" />
        <origin xyz="0.0 0.0 0.0" />
        <inertia ixx="0.000039" ixy="0.000000" ixz="0.000000"
          iyx="0.000000" iyy="0.000005" iyz="0.000000"
          izx="0.000000" izy="0.000000" izz="0.000035" />
      </inertial>
    </link>

    <joint name="robotiq_85_left_finger_tip_joint" type="revolute">
      <parent link="robotiq_85_left_inner_knuckle_link" />
      <child link="robotiq_85_left_finger_tip_link" />
      <axis xyz="0 0 1" />
      <origin xyz="0.04303959807 -0.03759940821 0.0" rpy="0.0 0.0 0.0" />
      <limit lower="-3.14" upper="3.14" velocity="3.14" effort="0.1" />
      <mimic joint="robotiq_85_left_knuckle_joint" multiplier="-1" />
    </joint>

    <joint name="robotiq_85_right_finger_tip_joint" type="revolute">
      <parent link="robotiq_85_right_inner_knuckle_link" />
      <child link="robotiq_85_right_finger_tip_link" />
      <axis xyz="0 0 1" />
      <origin rpy="0.0 0.0 0.0" xyz="0.04303959807 -0.03759940821  0.0" />
      <limit lower="-3.14" upper="3.14" velocity="3.14" effort="0.1" />
      <mimic joint="robotiq_85_left_knuckle_joint" multiplier="-1" />
    </joint>


    <link name="robotiq_85_left_finger_tip_link">
      <visual>
        <origin rpy="0 0 0" xyz="0 0 0" />
        <geometry>
          <mesh
            filename="file://$(find gazebo_env)/meshes/ur5e_nvidia/robotiq_85_gripper/visual/robotiq_85_finger_tip_link.dae" />
        </geometry>
      </visual>
      <collision>
        <geometry>
          <mesh
            filename="file://$(find gazebo_env)/meshes/ur5e_nvidia/robotiq_85_gripper/collision/robotiq_85_finger_tip_link.stl" />
        </geometry>
      </collision>
      <inertial>
        <mass value="0.019555" />
        <origin xyz="0.0 0.0 0.0" />
        <inertia ixx="0.000002" ixy="0.000000" ixz="0.000000"
          iyx="0.000000" iyy="0.000005" iyz="0.000000"
          izx="0.000000" izy="0.000000" izz="0.000006" />
      </inertial>
    </link>

    <link name="robotiq_85_right_finger_tip_link">
      <visual>
        <origin rpy="0 0 0" xyz="0 0 0" />
        <geometry>
          <mesh
            filename="file://$(find gazebo_env)/meshes/ur5e_nvidia/robotiq_85_gripper/visual/robotiq_85_finger_tip_link.dae" />
        </geometry>
      </visual>
      <collision>
        <geometry>
          <mesh
            filename="file://$(find gazebo_env)/meshes/ur5e_nvidia/robotiq_85_gripper/collision/robotiq_85_finger_tip_link.stl" />
        </geometry>
      </collision>
      <inertial>
        <mass value="0.019555" />
        <origin xyz="0.0 0.0 0.0" />
        <inertia ixx="0.000002" ixy="0.000000" ixz="0.000000"
          iyx="0.000000" iyy="0.000005" iyz="0.000000"
          izx="0.000000" izy="0.000000" izz="0.000006" />
      </inertial>
    </link>

    <!-- <ros2_control name="URBot" type="system">
    <hardware>
        <plugin>gazebo_ros2_control/GazeboSystem</plugin>
    </hardware>
  </ros2_control>
  <gazebo>
      <plugin filename="libgazebo_ros2_control.so" name="gazebo_ros2_control">
          <parameters>
              /home/benchturtle/cross_embodiment_ws/src/gazebo_env/bringup/config/basic_controller.yaml
          </parameters>
      </plugin>
  </gazebo> -->
    <gazebo>
      <plugin name="no_physics" filename="libno_physics_plugin.so" />
    </gazebo>
    <gazebo>
      <plugin name="gripper_control" filename="libgripper_control_plugin.so" />
    </gazebo>
  </xacro:macro>
</robot>