<?xml version="1.0" encoding="utf-8"?>
<!-- =================================================================================== -->
<!-- |    This document was autogenerated by xacro from ur5e_robot.urdf.xacro          | -->
<!-- |    EDITING THIS FILE BY HAND IS NOT RECOMMENDED                                 | -->
<!-- =================================================================================== -->
<robot name="ur5_no_gripper" xmlns:xacro="http://ros.org/wiki/xacro">
  <xacro:macro name="ur5_no_gripper"
    params="parent:=world *origin name:=ur5_no_gripper">
    <joint name="ur5_no_gripper_base_joint" type="fixed">
      <xacro:insert_block name="origin" />
      <parent link="${parent}" />
      <child link="ur5_no_gripper_base_link" />
    </joint>
    <link name="ur5_no_gripper_base_link" />
    <link name="ur5_no_gripper_base_link_inertia">
      <visual>
        <origin rpy="0 0 3.141592653589793" xyz="0 0 0" />
        <geometry>
          <mesh filename="file://$(find gazebo_env)/meshes/ur5/visual/base.dae" />
        </geometry>
      </visual>
      <collision>
        <origin rpy="0 0 3.141592653589793" xyz="0 0 0" />
        <geometry>
          <mesh filename="file://$(find gazebo_env)/meshes/ur5/collision/base.stl" />
        </geometry>
      </collision>
      <inertial>
        <mass value="4.0" />
        <origin rpy="0 0 0" xyz="0 0 0" />
        <inertia ixx="0.00443333156" ixy="0.0" ixz="0.0" iyy="0.00443333156" iyz="0.0" izz="0.0072" />
      </inertial>
    </link>
    <link name="ur5_no_gripper_shoulder_link">
      <visual>
        <origin rpy="0 0 3.141592653589793" xyz="0 0 0" />
        <geometry>
          <mesh filename="file://$(find gazebo_env)/meshes/ur5/visual/shoulder.dae" />
        </geometry>
      </visual>
      <collision>
        <origin rpy="0 0 3.141592653589793" xyz="0 0 0" />
        <geometry>
          <mesh filename="file://$(find gazebo_env)/meshes/ur5/collision/shoulder.stl" />
        </geometry>
      </collision>
      <inertial>
        <mass value="3.7" />
        <origin rpy="0 0 0" xyz="0 0 0" />
        <inertia ixx="0.014972352344389999" ixy="0.0" ixz="0.0" iyy="0.014972352344389999" iyz="0.0"
          izz="0.01040625" />
      </inertial>
    </link>
    <link name="ur5_no_gripper_upper_arm_link">
      <visual>
        <origin rpy="1.5707963267948966 0 -1.5707963267948966" xyz="0 0 0.13585" />
        <geometry>
          <mesh filename="file://$(find gazebo_env)/meshes/ur5/visual/upperarm.dae" />
        </geometry>
      </visual>
      <collision>
        <origin rpy="1.5707963267948966 0 -1.5707963267948966" xyz="0 0 0.13585" />
        <geometry>
          <mesh filename="file://$(find gazebo_env)/meshes/ur5/collision/upperarm.stl" />
        </geometry>
      </collision>
      <inertial>
        <mass value="8.393" />
        <origin rpy="0 1.5707963267948966 0" xyz="-0.2125 0.0 0.136" />
        <inertia ixx="0.1338857818623325" ixy="0.0" ixz="0.0" iyy="0.1338857818623325" iyz="0.0"
          izz="0.0151074" />
      </inertial>
    </link>
    <link name="ur5_no_gripper_forearm_link">
      <visual>
        <origin rpy="1.5707963267948966 0 -1.5707963267948966" xyz="0 0 0.0165" />
        <geometry>
          <mesh filename="file://$(find gazebo_env)/meshes/ur5/visual/forearm.dae" />
        </geometry>
      </visual>
      <collision>
        <origin rpy="1.5707963267948966 0 -1.5707963267948966" xyz="0 0 0.0165" />
        <geometry>
          <mesh filename="file://$(find gazebo_env)/meshes/ur5/collision/forearm.stl" />
        </geometry>
      </collision>
      <inertial>
        <mass value="2.275" />
        <origin rpy="0 1.5707963267948966 0" xyz="-0.196125 0.0 0.0165" />
        <inertia ixx="0.03121679102890359" ixy="0.0" ixz="0.0" iyy="0.03121679102890359" iyz="0.0"
          izz="0.004095" />
      </inertial>
    </link>
    <link name="ur5_no_gripper_wrist_1_link">
      <visual>
        <origin rpy="1.5707963267948966 0 0" xyz="0 0 -0.093" />
        <geometry>
          <mesh filename="file://$(find gazebo_env)/meshes/ur5/visual/wrist1.dae" />
        </geometry>
      </visual>
      <collision>
        <origin rpy="1.5707963267948966 0 0" xyz="0 0 -0.093" />
        <geometry>
          <mesh filename="file://$(find gazebo_env)/meshes/ur5/collision/wrist1.stl" />
        </geometry>
      </collision>
      <inertial>
        <mass value="1.219" />
        <origin rpy="0 0 0" xyz="0 0 0" />
        <inertia ixx="0.0020138887777775" ixy="0.0" ixz="0.0" iyy="0.0020138887777775" iyz="0.0"
          izz="0.0021942" />
      </inertial>
    </link>
    <link name="ur5_no_gripper_wrist_2_link">
      <visual>
        <origin rpy="0 0 0" xyz="0 0 -0.095" />
        <geometry>
          <mesh filename="file://$(find gazebo_env)/meshes/ur5/visual/wrist2.dae" />
        </geometry>
      </visual>
      <collision>
        <origin rpy="0 0 0" xyz="0 0 -0.095" />
        <geometry>
          <mesh filename="file://$(find gazebo_env)/meshes/ur5/collision/wrist2.stl" />
        </geometry>
      </collision>
      <inertial>
        <mass value="1.219" />
        <origin rpy="0 0 0" xyz="0 0 0" />
        <inertia ixx="0.0018310388509175" ixy="0.0" ixz="0.0" iyy="0.0018310388509175" iyz="0.0"
          izz="0.0021942" />
      </inertial>
    </link>
    <link name="ur5_no_gripper_wrist_3_link">
      <visual>
        <origin rpy="1.5707963267948966 0 0" xyz="0 0 -0.0818" />
        <geometry>
          <mesh filename="file://$(find gazebo_env)/meshes/ur5/visual/wrist3.dae" />
        </geometry>
      </visual>
      <collision>
        <origin rpy="1.5707963267948966 0 0" xyz="0 0 -0.0818" />
        <geometry>
          <mesh filename="file://$(find gazebo_env)/meshes/ur5/collision/wrist3.stl" />
        </geometry>
      </collision>
      <inertial>
        <mass value="0.1879" />
        <origin rpy="0 0 0" xyz="0.0 0.0 -0.01525" />
        <inertia ixx="8.062472608343e-05" ixy="0.0" ixz="0.0" iyy="8.062472608343e-05" iyz="0.0"
          izz="0.0001321171875" />
      </inertial>
    </link>
    <!-- joints - main serial chain -->
    <joint name="ur5_no_gripper_base_link-base_link_inertia" type="fixed">
      <parent link="ur5_no_gripper_base_link" />
      <child link="ur5_no_gripper_base_link_inertia" />
      <!-- 'base_link' is REP-103 aligned (so X+ forward), while the internal
             frames of the robot/controller have X+ pointing backwards.
             Use the joint between 'base_link' and 'base_link_inertia' (a dummy
             link/frame) to introduce the necessary rotation over Z (of pi rad).
        -->
      <origin rpy="0 0 3.141592653589793" xyz="0 0 0" />
    </joint>
    <joint name="ur5_no_gripper_shoulder_pan_joint" type="revolute">
      <parent link="ur5_no_gripper_base_link_inertia" />
      <child link="ur5_no_gripper_shoulder_link" />
      <origin rpy="0 0 0" xyz="0 0 0.089159" />
      <axis xyz="0 0 1" />
      <limit effort="150.0" lower="-6.283185307179586" upper="6.283185307179586"
        velocity="3.141592653589793" />
      <safety_controller k_position="20" k_velocity="0.0" soft_lower_limit="-6.133185307179586"
        soft_upper_limit="6.133185307179586" />
      <dynamics damping="0" friction="0" />
    </joint>
    <joint name="ur5_no_gripper_shoulder_lift_joint" type="revolute">
      <parent link="ur5_no_gripper_shoulder_link" />
      <child link="ur5_no_gripper_upper_arm_link" />
      <origin rpy="1.570796327 0 0" xyz="0 0 0" />
      <axis xyz="0 0 1" />
      <limit effort="150.0" lower="-6.283185307179586" upper="6.283185307179586"
        velocity="3.141592653589793" />
      <safety_controller k_position="20" k_velocity="0.0" soft_lower_limit="-6.133185307179586"
        soft_upper_limit="6.133185307179586" />
      <dynamics damping="0" friction="0" />
    </joint>
    <joint name="ur5_no_gripper_elbow_joint" type="revolute">
      <parent link="ur5_no_gripper_upper_arm_link" />
      <child link="ur5_no_gripper_forearm_link" />
      <origin rpy="0 0 0" xyz="-0.425 0 0" />
      <axis xyz="0 0 1" />
      <limit effort="150.0" lower="-3.141592653589793" upper="3.141592653589793"
        velocity="3.141592653589793" />
      <safety_controller k_position="20" k_velocity="0.0" soft_lower_limit="-2.991592653589793"
        soft_upper_limit="2.991592653589793" />
      <dynamics damping="0" friction="0" />
    </joint>
    <joint name="ur5_no_gripper_wrist_1_joint" type="revolute">
      <parent link="ur5_no_gripper_forearm_link" />
      <child link="ur5_no_gripper_wrist_1_link" />
      <origin rpy="0 0 0" xyz="-0.39225 0 0.10915" />
      <axis xyz="0 0 1" />
      <limit effort="28.0" lower="-6.283185307179586" upper="6.283185307179586"
        velocity="3.141592653589793" />
      <safety_controller k_position="20" k_velocity="0.0" soft_lower_limit="-6.133185307179586"
        soft_upper_limit="6.133185307179586" />
      <dynamics damping="0" friction="0" />
    </joint>
    <joint name="ur5_no_gripper_wrist_2_joint" type="revolute">
      <parent link="ur5_no_gripper_wrist_1_link" />
      <child link="ur5_no_gripper_wrist_2_link" />
      <origin rpy="1.570796327 0 0" xyz="0 -0.09465 -1.941303950897609e-11" />
      <axis xyz="0 0 1" />
      <limit effort="28.0" lower="-6.283185307179586" upper="6.283185307179586"
        velocity="3.141592653589793" />
      <safety_controller k_position="20" k_velocity="0.0" soft_lower_limit="-6.133185307179586"
        soft_upper_limit="6.133185307179586" />
      <dynamics damping="0" friction="0" />
    </joint>
    <joint name="ur5_no_gripper_wrist_3_joint" type="revolute">
      <parent link="ur5_no_gripper_wrist_2_link" />
      <child link="ur5_no_gripper_wrist_3_link" />
      <origin rpy="1.570796326589793 3.141592653589793 3.141592653589793"
        xyz="0 0.0823 -1.688001216681175e-11" />
      <axis xyz="0 0 1" />
      <limit effort="28.0" lower="-6.283185307179586" upper="6.283185307179586"
        velocity="3.141592653589793" />
      <safety_controller k_position="20" k_velocity="0.0" soft_lower_limit="-6.133185307179586"
        soft_upper_limit="6.133185307179586" />
      <dynamics damping="0" friction="0" />
    </joint>
    <link name="ur5_no_gripper_ft_frame" />
    <joint name="ur5_no_gripper_wrist_3_link-ft_frame" type="fixed">
      <parent link="ur5_no_gripper_wrist_3_link" />
      <child link="ur5_no_gripper_ft_frame" />
      <origin rpy="3.141592653589793 0 0" xyz="0 0 0" />
    </joint>
    <!-- ROS-Industrial 'base' frame - base_link to UR 'Base' Coordinates transform -->
    <link name="ur5_no_gripper_base" />
    <joint name="ur5_no_gripper_base_link-base_fixed_joint" type="fixed">
      <!-- Note the rotation over Z of pi radians - as base_link is REP-103
             aligned (i.e., has X+ forward, Y+ left and Z+ up), this is needed
             to correctly align 'base' with the 'Base' coordinate system of
             the UR controller.
        -->
      <origin rpy="0 0 3.141592653589793" xyz="0 0 0" />
      <parent link="ur5_no_gripper_base_link" />
      <child link="ur5_no_gripper_base" />
    </joint>
    <!-- ROS-Industrial 'flange' frame - attachment point for EEF models -->
    <link name="ur5_no_gripper_flange" />
    <joint name="ur5_no_gripper_wrist_3-flange" type="fixed">
      <parent link="ur5_no_gripper_wrist_3_link" />
      <child link="ur5_no_gripper_flange" />
      <origin rpy="0 -1.5707963267948966 -1.5707963267948966" xyz="0 0 0" />
    </joint>
    <!-- ROS-Industrial 'tool0' frame - all-zeros tool frame -->
    <link name="ur5_no_gripper_tool0" />
    <joint name="ur5_no_gripper_flange-tool0" type="fixed">
      <!-- default toolframe - X+ left, Y+ up, Z+ front -->
      <origin rpy="1.5707963267948966 0 1.5707963267948966" xyz="0 0 0" />
      <parent link="ur5_no_gripper_flange" />
      <child link="ur5_no_gripper_tool0" />
    </joint>
    <joint name="ur5_no_gripper_tool0-ur5_ee_gripper" type="fixed">
      <origin rpy="0 0 0" xyz="0 0 0.143" />
      <parent link="ur5_no_gripper_tool0" />
      <child link="ur5_no_gripper_ur5_ee_gripper" />
    </joint>
    <link name="ur5_no_gripper_ur5_ee_gripper" />
  </xacro:macro>
</robot>