<?xml version="1.0" encoding="utf-8"?>
<!-- =================================================================================== -->
<!-- |    This document was autogenerated by xacro from ur5e_robot.urdf.xacro          | -->
<!-- |    EDITING THIS FILE BY HAND IS NOT RECOMMENDED                                 | -->
<!-- =================================================================================== -->
<robot name="ur5e_gripper" xmlns:xacro="http://ros.org/wiki/xacro">
  <xacro:macro name="ur5e_gripper"
    params="parent:=world *origin name:=ur5e_gripper">
    <joint name="base_joint" type="fixed">
      <xacro:insert_block name="origin" />
      <parent link="${parent}" />
      <child link="base_link" />
    </joint>
    <link name="base_link">
      <visual>
        <origin rpy="0 0 0" xyz="0 0 0" />
        <geometry>
          <mesh filename="file://$(find gazebo_env)/meshes/ur5e_nvidia/ur5e/visual/base.dae" />
        </geometry>
        <material name="LightGrey">
          <color rgba="0.7 0.7 0.7 1.0" />
        </material>
      </visual>
      <collision>
        <geometry>
          <mesh filename="file://$(find gazebo_env)/meshes/ur5e_nvidia/ur5e/collision/base.stl"
            scale="1.0 1.0 1.0" />
        </geometry>
      </collision>
      <inertial>
        <mass value="4.0" />
        <origin rpy="0 0 0" xyz="0.0 0.0 0.0" />
        <inertia ixx="0.00443333156" ixy="0.0" ixz="0.0" iyy="0.00443333156" iyz="0.0" izz="0.0072" />
      </inertial>
    </link>
    <joint name="shoulder_pan_joint" type="revolute">
      <parent link="base_link" />
      <child link="shoulder_link" />
      <origin rpy="0.0 0.0 0.0" xyz="0.0 0.0 0.163" />
      <axis xyz="0 0 1" />
      <limit effort="150.0" lower="-6.28318530718" upper="6.28318530718" velocity="3.14" />
      <dynamics damping="0.0" friction="0.0" />
    </joint>
    <link name="shoulder_link">
      <visual>
        <origin rpy="0 0 0" xyz="0 0 0" />
        <geometry>
          <mesh filename="file://$(find gazebo_env)/meshes/ur5e_nvidia/ur5e/visual/shoulder.dae" />
        </geometry>
        <material name="LightGrey">
          <color rgba="0.7 0.7 0.7 1.0" />
        </material>
      </visual>
      <collision>
        <geometry>
          <mesh filename="file://$(find gazebo_env)/meshes/ur5e_nvidia/ur5e/collision/shoulder.stl"
            scale="1.0 1.0 1.0" />
        </geometry>
      </collision>
      <inertial>
        <mass value="3.7" />
        <origin rpy="0 0 0" xyz="0.0 0.0 0.0" />
        <inertia ixx="0.010267495893" ixy="0.0" ixz="0.0" iyy="0.010267495893" iyz="0.0"
          izz="0.00666" />
      </inertial>
    </link>
    <joint name="shoulder_lift_joint" type="revolute">
      <parent link="shoulder_link" />
      <child link="upper_arm_link" />
      <origin rpy="0.0 1.57079632679 0.0" xyz="0.0 0.138 0.0" />
      <axis xyz="0 1 0" />
      <limit effort="150.0" lower="-6.28318530718" upper="6.28318530718" velocity="3.14" />
      <dynamics damping="0.0" friction="0.0" />
    </joint>
    <link name="upper_arm_link">
      <visual>
        <origin rpy="0 0 0" xyz="0 0 0" />
        <origin rpy="0 0 0" xyz="0 0 0" />
        <geometry>
          <mesh filename="file://$(find gazebo_env)/meshes/ur5e_nvidia/ur5e/visual/upperarm.dae" />
        </geometry>
        <material name="LightGrey">
          <color rgba="0.7 0.7 0.7 1.0" />
        </material>
      </visual>
      <collision>
        <geometry>
          <mesh filename="file://$(find gazebo_env)/meshes/ur5e_nvidia/ur5e/collision/upperarm.stl"
            scale="1.0 1.0 1.0" />
        </geometry>
      </collision>
      <inertial>
        <mass value="8.393" />
        <origin rpy="0 0 0" xyz="0.0 0.0 0.2125" />
        <inertia ixx="0.133885781862" ixy="0.0" ixz="0.0" iyy="0.133885781862" iyz="0.0"
          izz="0.0151074" />
      </inertial>
    </link>
    <joint name="elbow_joint" type="revolute">
      <parent link="upper_arm_link" />
      <child link="forearm_link" />
      <origin rpy="0.0 0.0 0.0" xyz="0.0 -0.131 0.425" />
      <axis xyz="0 1 0" />
      <limit effort="150.0" lower="-3.14159265359" upper="3.14159265359" velocity="3.14" />
      <dynamics damping="0.0" friction="0.0" />
    </joint>
    <link name="forearm_link">
      <visual>
        <origin rpy="0 0 0" xyz="0 0 0" />
        <geometry>
          <mesh filename="file://$(find gazebo_env)/meshes/ur5e_nvidia/ur5e/visual/forearm.dae" />
        </geometry>
        <material name="LightGrey">
          <color rgba="0.7 0.7 0.7 1.0" />
        </material>
      </visual>
      <collision>
        <geometry>
          <mesh filename="file://$(find gazebo_env)/meshes/ur5e_nvidia/ur5e/collision/forearm.stl"
            scale="1.0 1.0 1.0" />
        </geometry>
      </collision>
      <inertial>
        <mass value="2.275" />
        <origin rpy="0 0 0" xyz="0.0 0.0 0.196" />
        <inertia ixx="0.0311796208615" ixy="0.0" ixz="0.0" iyy="0.0311796208615" iyz="0.0"
          izz="0.004095" />
      </inertial>
    </link>
    <joint name="wrist_1_joint" type="revolute">
      <parent link="forearm_link" />
      <child link="wrist_1_link" />
      <origin rpy="0.0 1.57079632679 0.0" xyz="0.0 0.0 0.392" />
      <axis xyz="0 1 0" />
      <limit effort="28.0" lower="-6.28318530718" upper="6.28318530718" velocity="6.28" />
      <dynamics damping="0.0" friction="0.0" />
    </joint>
    <link name="wrist_1_link">
      <visual>
        <origin rpy="0 0 0" xyz="0 0 0" />
        <geometry>
          <mesh filename="file://$(find gazebo_env)/meshes/ur5e_nvidia/ur5e/visual/wrist1.dae" />
        </geometry>
        <material name="LightGrey">
          <color rgba="0.7 0.7 0.7 1.0" />
        </material>
      </visual>
      <collision>
        <geometry>
          <mesh filename="file://$(find gazebo_env)/meshes/ur5e_nvidia/ur5e/collision/wrist1.stl"
            scale="1.0 1.0 1.0" />
        </geometry>
      </collision>
      <inertial>
        <mass value="1.219" />
        <origin rpy="0 0 0" xyz="0.0 0.127 0.0" />
        <inertia ixx="0.00255989897604" ixy="0.0" ixz="0.0" iyy="0.00255989897604" iyz="0.0"
          izz="0.0021942" />
      </inertial>
    </link>
    <joint name="wrist_2_joint" type="revolute">
      <parent link="wrist_1_link" />
      <child link="wrist_2_link" />
      <origin rpy="0.0 0.0 0.0" xyz="0.0 0.127 0.0" />
      <axis xyz="0 0 1" />
      <limit effort="28.0" lower="-6.28318530718" upper="6.28318530718" velocity="6.28" />
      <dynamics damping="0.0" friction="0.0" />
    </joint>
    <link name="wrist_2_link">
      <visual>
        <origin rpy="0 0 0" xyz="0 0 0" />
        <geometry>
          <mesh filename="file://$(find gazebo_env)/meshes/ur5e_nvidia/ur5e/visual/wrist2.dae" />
        </geometry>
        <material name="LightGrey">
          <color rgba="0.7 0.7 0.7 1.0" />
        </material>
      </visual>
      <collision>
        <geometry>
          <mesh filename="file://$(find gazebo_env)/meshes/ur5e_nvidia/ur5e/collision/wrist2.stl"
            scale="1.0 1.0 1.0" />
        </geometry>
      </collision>
      <inertial>
        <mass value="1.219" />
        <origin rpy="0 0 0" xyz="0.0 0.0 0.1" />
        <inertia ixx="0.00255989897604" ixy="0.0" ixz="0.0" iyy="0.00255989897604" iyz="0.0"
          izz="0.0021942" />
      </inertial>
    </link>
    <joint name="wrist_3_joint" type="revolute">
      <parent link="wrist_2_link" />
      <child link="wrist_3_link" />
      <origin rpy="0.0 0.0 0.0" xyz="0.0 0.0 0.1" />
      <axis xyz="0 1 0" />
      <limit effort="28.0" lower="-6.28318530718" upper="6.28318530718" velocity="6.28" />
      <dynamics damping="0.0" friction="0.0" />
    </joint>
    <link name="wrist_3_link">
      <visual>
        <origin rpy="0 0 0" xyz="0 0 0" />
        <geometry>
          <mesh filename="file://$(find gazebo_env)/meshes/ur5e_nvidia/ur5e/visual/wrist3.dae" />
        </geometry>
        <material name="LightGrey">
          <color rgba="0.7 0.7 0.7 1.0" />
        </material>
      </visual>
      <collision>
        <geometry>
          <mesh filename="file://$(find gazebo_env)/meshes/ur5e_nvidia/ur5e/collision/wrist3.stl"
            scale="1.0 1.0 1.0" />
        </geometry>
      </collision>
      <inertial>
        <mass value="0.1879" />
        <origin rpy="1.57079632679 0 0" xyz="0.0 0.0771 0.0" />
        <inertia ixx="9.89041005217e-05" ixy="0.0" ixz="0.0" iyy="9.89041005217e-05" iyz="0.0"
          izz="0.0001321171875" />
      </inertial>
    </link>
    <joint name="ee_fixed_joint" type="fixed">
      <parent link="wrist_3_link" />
      <child link="ee_link" />
      <origin rpy="0.0 0.0 1.57079632679" xyz="0.0 0.1 0.0" />
    </joint>
    <link name="ee_link">
      <collision>
        <geometry>
          <box size="0.01 0.01 0.01" />
        </geometry>
        <origin rpy="0 0 0" xyz="-0.01 0 0" />
      </collision>
    </link>
    <joint name="arm_gripper_joint" type="fixed">
      <parent link="wrist_3_link" />
      <child link="robotiq_85_base_link" />
      <origin rpy="1.5708 0.0 1.5708" xyz="0.0 0.089 0.0" />
    </joint>
    <link name="robotiq_85_base_link">
      <visual>
        <origin rpy="0 0 0" xyz="0 0 0" />
        <geometry>
          <mesh
            filename="file://$(find gazebo_env)/meshes/ur5e_nvidia/robotiq_85_gripper/visual/robotiq_85_base_link.dae" />
        </geometry>
      </visual>
      <collision>
        <geometry>
          <mesh
            filename="file://$(find gazebo_env)/meshes/ur5e_nvidia/robotiq_85_gripper/collision/robotiq_85_base_link.stl" />
        </geometry>
      </collision>
      <inertial>
        <mass value="0.636951" />
        <origin xyz="0.0 0.0 0.0" />
        <inertia ixx="0.000380" ixy="0.000000" ixz="0.000000"
          iyx="0.000000" iyy="0.001110" iyz="0.000000"
          izx="0.000000" izy="0.000000" izz="0.001171" />
      </inertial>
    </link>
    <joint name="robotiq_85_left_knuckle_joint" type="revolute">
      <parent link="robotiq_85_base_link" />
      <child link="robotiq_85_left_knuckle_link" />
      <axis xyz="0 0 1" />
      <origin rpy="3.14 0.0 0.0" xyz="0.05490451627 0.03060114443 0.0" />
      <limit lower="0.0" upper="0.80285" velocity="3.14" effort="1000" />
    </joint>

    <joint name="robotiq_85_right_knuckle_joint" type="revolute">
      <parent link="robotiq_85_base_link" />
      <child link="robotiq_85_right_knuckle_link" />
      <axis xyz="0 0 1" />
      <origin rpy="0.0 0.0 0.0" xyz="0.05490451627 -0.03060114443 0.0" />
      <limit lower="-3.14" upper="3.14" velocity="3.14" effort="1000" />
      <mimic joint="robotiq_85_left_knuckle_joint" />
    </joint>

    <link name="robotiq_85_left_knuckle_link">
      <visual>
        <origin rpy="0 0 0" xyz="0 0 0" />
        <geometry>
          <mesh
            filename="file://$(find gazebo_env)/meshes/ur5e_nvidia/robotiq_85_gripper/visual/robotiq_85_knuckle_link.dae" />
        </geometry>
      </visual>
      <collision>
        <geometry>
          <mesh
            filename="file://$(find gazebo_env)/meshes/ur5e_nvidia/robotiq_85_gripper/collision/robotiq_85_knuckle_link.stl" />
        </geometry>
      </collision>
      <inertial>
        <mass value="0.018491" />
        <origin xyz="0.0 0.0 0.0" />
        <inertia ixx="0.000009" ixy="-0.000001" ixz="0.000000"
          iyx="-0.000001" iyy="0.000001" iyz="0.000000"
          izx="0.000000" izy="0.000000" izz="0.000010" />
      </inertial>
    </link>

    <link name="robotiq_85_right_knuckle_link">
      <visual>
        <origin rpy="0 0 0" xyz="0 0 0" />
        <geometry>
          <mesh
            filename="file://$(find gazebo_env)/meshes/ur5e_nvidia/robotiq_85_gripper/visual/robotiq_85_knuckle_link.dae" />
        </geometry>
      </visual>
      <collision>
        <geometry>
          <mesh
            filename="file://$(find gazebo_env)/meshes/ur5e_nvidia/robotiq_85_gripper/collision/robotiq_85_knuckle_link.stl" />
        </geometry>
      </collision>
      <inertial>
        <mass value="0.018491" />
        <origin xyz="0.0 0.0 0.0" />
        <inertia ixx="0.000009" ixy="-0.000001" ixz="0.000000"
          iyx="-0.000001" iyy="0.000001" iyz="0.000000"
          izx="0.000000" izy="0.000000" izz="0.000010" />
      </inertial>
    </link>

    <joint name="robotiq_85_left_finger_joint" type="fixed">
      <parent link="robotiq_85_left_knuckle_link" />
      <child link="robotiq_85_left_finger_link" />
      <origin xyz="-0.00408552455 -0.03148604435 0.0" rpy="0 0 0" />
    </joint>

    <joint name="robotiq_85_right_finger_joint" type="fixed">
      <parent link="robotiq_85_right_knuckle_link" />
      <child link="robotiq_85_right_finger_link" />
      <origin xyz="-0.00408552455 -0.03148604435 0.0" rpy="0 0 0" />
    </joint>

    <link name="robotiq_85_left_finger_link">
      <visual>
        <origin rpy="0 0 0" xyz="0 0 0" />
        <geometry>
          <mesh
            filename="file://$(find gazebo_env)/meshes/ur5e_nvidia/robotiq_85_gripper/visual/robotiq_85_finger_link.dae" />
        </geometry>
      </visual>
      <collision>
        <geometry>
          <mesh
            filename="file://$(find gazebo_env)/meshes/ur5e_nvidia/robotiq_85_gripper/collision/robotiq_85_finger_link.stl" />
        </geometry>
      </collision>
      <inertial>
        <mass value="0.027309" />
        <origin xyz="0.0 0.0 0.0" />
        <inertia ixx="0.000003" ixy="-0.000002" ixz="0.000000"
          iyx="-0.000002" iyy="0.000021" iyz="0.000000"
          izx="0.000000" izy="0.000000" izz="0.000020" />
      </inertial>
    </link>

    <link name="robotiq_85_right_finger_link">
      <visual>
        <origin rpy="0 0 0" xyz="0 0 0" />
        <geometry>
          <mesh
            filename="file://$(find gazebo_env)/meshes/ur5e_nvidia/robotiq_85_gripper/visual/robotiq_85_finger_link.dae" />
        </geometry>
      </visual>
      <collision>
        <geometry>
          <mesh
            filename="file://$(find gazebo_env)/meshes/ur5e_nvidia/robotiq_85_gripper/collision/robotiq_85_finger_link.stl" />
        </geometry>
      </collision>
      <inertial>
        <mass value="0.027309" />
        <origin xyz="0.0 0.0 0.0" />
        <inertia ixx="0.000003" ixy="-0.000002" ixz="0.000000"
          iyx="-0.000002" iyy="0.000021" iyz="0.000000"
          izx="0.000000" izy="0.000000" izz="0.000020" />
      </inertial>
    </link>

    <joint name="robotiq_85_left_inner_knuckle_joint" type="revolute">
      <parent link="robotiq_85_base_link" />
      <child link="robotiq_85_left_inner_knuckle_link" />
      <axis xyz="0 0 1" />
      <origin xyz="0.06142 0.0127 0" rpy="3.14 0.0 0.0" />
      <limit lower="-3.14" upper="3.14" velocity="3.14" effort="0.1" />
      <mimic joint="robotiq_85_left_knuckle_joint" offset="0" />
    </joint>

    <joint name="robotiq_85_right_inner_knuckle_joint" type="revolute">
      <parent link="robotiq_85_base_link" />
      <child link="robotiq_85_right_inner_knuckle_link" />
      <axis xyz="0 0 1" />
      <origin xyz="0.06142 -0.0127 0" rpy="0 0 0" />
      <limit lower="-3.14" upper="3.14" velocity="3.14" effort="0.1" />
      <mimic joint="robotiq_85_left_knuckle_joint" offset="0" />
    </joint>

    <link name="robotiq_85_left_inner_knuckle_link">
      <visual>
        <origin rpy="0 0 0" xyz="0 0 0" />
        <geometry>
          <mesh
            filename="file://$(find gazebo_env)/meshes/ur5e_nvidia/robotiq_85_gripper/visual/robotiq_85_inner_knuckle_link.dae" />
        </geometry>
      </visual>
      <collision>
        <geometry>
          <mesh
            filename="file://$(find gazebo_env)/meshes/ur5e_nvidia/robotiq_85_gripper/collision/robotiq_85_inner_knuckle_link.stl" />
        </geometry>
      </collision>
      <inertial>
        <mass value="0.029951" />
        <origin xyz="0.0 0.0 0.0" />
        <inertia ixx="0.000039" ixy="0.000000" ixz="0.000000"
          iyx="0.000000" iyy="0.000005" iyz="0.000000"
          izx="0.000000" izy="0.000000" izz="0.000035" />
      </inertial>
    </link>
    <link name="robotiq_85_right_inner_knuckle_link">
      <visual>
        <origin rpy="0 0 0" xyz="0 0 0" />
        <geometry>
          <mesh
            filename="file://$(find gazebo_env)/meshes/ur5e_nvidia/robotiq_85_gripper/visual/robotiq_85_inner_knuckle_link.dae" />
        </geometry>
      </visual>
      <collision>
        <geometry>
          <mesh
            filename="file://$(find gazebo_env)/meshes/ur5e_nvidia/robotiq_85_gripper/collision/robotiq_85_inner_knuckle_link.stl" />
        </geometry>
      </collision>
      <inertial>
        <mass value="0.029951" />
        <origin xyz="0.0 0.0 0.0" />
        <inertia ixx="0.000039" ixy="0.000000" ixz="0.000000"
          iyx="0.000000" iyy="0.000005" iyz="0.000000"
          izx="0.000000" izy="0.000000" izz="0.000035" />
      </inertial>
    </link>

    <joint name="robotiq_85_left_finger_tip_joint" type="revolute">
      <parent link="robotiq_85_left_inner_knuckle_link" />
      <child link="robotiq_85_left_finger_tip_link" />
      <axis xyz="0 0 1" />
      <origin xyz="0.04303959807 -0.03759940821 0.0" rpy="0.0 0.0 0.0" />
      <limit lower="-3.14" upper="3.14" velocity="3.14" effort="0.1" />
      <mimic joint="robotiq_85_left_knuckle_joint" multiplier="-1" />
    </joint>

    <joint name="robotiq_85_right_finger_tip_joint" type="revolute">
      <parent link="robotiq_85_right_inner_knuckle_link" />
      <child link="robotiq_85_right_finger_tip_link" />
      <axis xyz="0 0 1" />
      <origin rpy="0.0 0.0 0.0" xyz="0.04303959807 -0.03759940821  0.0" />
      <limit lower="-3.14" upper="3.14" velocity="3.14" effort="0.1" />
      <mimic joint="robotiq_85_left_knuckle_joint" multiplier="-1" />
    </joint>


    <link name="robotiq_85_left_finger_tip_link">
      <visual>
        <origin rpy="0 0 0" xyz="0 0 0" />
        <geometry>
          <mesh
            filename="file://$(find gazebo_env)/meshes/ur5e_nvidia/robotiq_85_gripper/visual/robotiq_85_finger_tip_link.dae" />
        </geometry>
      </visual>
      <collision>
        <geometry>
          <mesh
            filename="file://$(find gazebo_env)/meshes/ur5e_nvidia/robotiq_85_gripper/collision/robotiq_85_finger_tip_link.stl" />
        </geometry>
      </collision>
      <inertial>
        <mass value="0.019555" />
        <origin xyz="0.0 0.0 0.0" />
        <inertia ixx="0.000002" ixy="0.000000" ixz="0.000000"
          iyx="0.000000" iyy="0.000005" iyz="0.000000"
          izx="0.000000" izy="0.000000" izz="0.000006" />
      </inertial>
    </link>

    <link name="robotiq_85_right_finger_tip_link">
      <visual>
        <origin rpy="0 0 0" xyz="0 0 0" />
        <geometry>
          <mesh
            filename="file://$(find gazebo_env)/meshes/ur5e_nvidia/robotiq_85_gripper/visual/robotiq_85_finger_tip_link.dae" />
        </geometry>
      </visual>
      <collision>
        <geometry>
          <mesh
            filename="file://$(find gazebo_env)/meshes/ur5e_nvidia/robotiq_85_gripper/collision/robotiq_85_finger_tip_link.stl" />
        </geometry>
      </collision>
      <inertial>
        <mass value="0.019555" />
        <origin xyz="0.0 0.0 0.0" />
        <inertia ixx="0.000002" ixy="0.000000" ixz="0.000000"
          iyx="0.000000" iyy="0.000005" iyz="0.000000"
          izx="0.000000" izy="0.000000" izz="0.000006" />
      </inertial>
    </link>


    <link name="tool0" />
    <joint name="wrist_3_link-tool0_fixed_joint" type="fixed">
      <origin rpy="-1.57079632679 0 0" xyz="0 0.1 0" />
      <parent link="wrist_3_link" />
      <child link="tool0" />
    </joint>
    <link name="ur5e_ee_link" />
    <joint name="tool0_to_ur5e_ee_link_fixed_joint" type="fixed">
      <origin rpy="0 0 0" xyz="0.000924756350 0.000929957310 0.142071136" />
      <parent link="tool0" />
      <child link="ur5e_ee_link" />
    </joint>

    <!-- <ros2_control name="URBot" type="system">
    <hardware>
        <plugin>gazebo_ros2_control/GazeboSystem</plugin>
    </hardware>
  </ros2_control>
  <gazebo>
      <plugin filename="libgazebo_ros2_control.so" name="gazebo_ros2_control">
          <parameters>
              /home/benchturtle/cross_embodiment_ws/src/gazebo_env/bringup/config/basic_controller.yaml
          </parameters>
      </plugin>
  </gazebo> -->
    <gazebo>
      <plugin name="no_physics" filename="libno_physics_plugin.so" />
    </gazebo>
    <gazebo>
      <plugin name="ur5e_control" filename="libur5e_control_plugin.so" />
    </gazebo>
  </xacro:macro>
</robot>